<?xml version="1.0" ?>

<robot name="2_link">
  <link name="base_link"/>
  <joint name="joint1" type="revolute">
    <parent link="base_link"/>
    <child link="link1"/>
    <origin rpy="0 0 0" xyz="0 0 0"/>
    <axis xyz="0 0 1"/>
  </joint>
  <link name="link1">
    <origin rpy="1.5707963267948966 0 0" xyz="0 0.5 0"/>
    <inertial>
      <origin rpy="1.5707963267948966 0 0" xyz="0 0.5 0"/>
      <mass value="0.1"/>
      <inertia ixx="0.008395833333333333" ixy="0.0" ixz="0.0" iyy="0.008395833333333333" iyz="0.0" izz="0.00012500000000000003"/>
    </inertial>
  </link>
  <joint name="joint2" type="revolute">
    <parent link="link1"/>
    <child link="link2"/>
    <origin rpy="0 0 0" xyz="0 1 0"/>
    <axis xyz="0 0 1"/>
  </joint>
  <link name="link2">
    <origin rpy="1.5707963267948966 0 0" xyz="0 0.5 0"/>
    <inertial>
      <origin rpy="1.5707963267948966 0 0" xyz="0 0.5 0"/>
      <mass value="0.1"/>
      <inertia ixx="0.008395833333333333" ixy="0.0" ixz="0.0" iyy="0.008395833333333333" iyz="0.0" izz="0.00012500000000000003"/>
    </inertial>
  </link>
    <joint name="joint3" type="revolute">
    <parent link="link2"/>
    <child link="link3"/>
    <origin rpy="0 0 0" xyz="0 1 0"/>
    <axis xyz="0 0 1"/>
  </joint>
  <link name="link3">
    <origin rpy="1.5707963267948966 0 0" xyz="0 0.5 0"/>
    <inertial>
      <origin rpy="1.5707963267948966 0 0" xyz="0 0.5 0"/>
      <mass value="0.1"/>
      <inertia ixx="0.008395833333333333" ixy="0.0" ixz="0.0" iyy="0.008395833333333333" iyz="0.0" izz="0.00012500000000000003"/>
    </inertial>
  </link>
</robot>
